Workbook

Sheet Sheet1
A1: Stats 2025 | C1: Total | E1: Passing | G1: Rushing | I1: Points | M1: Total | O1: Passing | Q1: Rushing | S1: Points | U1: Rank | W1: Power
A2: Offense (2025) | B2: GP | C2: YDS | D2: YDS/G | E2: YDS | F2: YDS/G | G2: YDS | H2: YDS/G | I2: PTS | J2: PTS/G | K2: offense/defense | L2: GP | M2: YDS | N2: YDS/G | O2: YDS | P2: YDS/G | Q2: YDS | R2: YDS/G | S2: PTS | T2: PTS/G | U2: Offense Rank | V2: Defense Rank | W2: Team Power
A3: Los Angeles Rams | B3: 17 | C3: 6709 | D3: 394.6 | E3: 4557 | F3: 268.1 | G3: 2152 | H3: 126.6 | I3: 518 | J3: 30.5 | K3: offense/defense | L3: 17 | M3: 5568 | N3: 327.5 | O3: 3684 | P3: 216.7 | Q3: 1884 | R3: 110.8 | S3: 346 | T3: 20.4 | U3: 14772.8 | V3: 12174.4 | W3: 2598.4
A4: Dallas Cowboys | B4: 17 | C4: 6663 | D4: 391.9 | E4: 4527 | F4: 266.3 | G4: 2136 | H4: 125.6 | I4: 471 | J4: 27.7 | K4: offense/defense | L4: 17 | M4: 6409 | N4: 377 | O4: 4276 | P4: 251.5 | Q4: 2133 | R4: 125.5 | S4: 511 | T4: 30.1 | U4: 14625.5 | V4: 14130.1 | W4: 495.4
A5: New England Patriots | B5: 17 | C5: 6449 | D5: 379.4 | E5: 4258 | F5: 250.5 | G5: 2191 | H5: 128.9 | I5: 490 | J5: 28.8 | K5: offense/defense | L5: 17 | M5: 5019 | N5: 295.2 | O5: 3290 | P5: 193.5 | Q5: 1729 | R5: 101.7 | S5: 320 | T5: 18.8 | U5: 14192.6 | V5: 10984.2 | W5: 3208.4
A6: Buffalo Bills | B6: 17 | C6: 6397 | D6: 376.3 | E6: 3683 | F6: 216.6 | G6: 2714 | H6: 159.6 | I6: 481 | J6: 28.3 | K6: offense/defense | L6: 17 | M6: 4983 | N6: 293.1 | O6: 2668 | P6: 156.9 | Q6: 2315 | R6: 136.2 | S6: 365 | T6: 21.5 | U6: 14072.8 | V6: 10955.7 | W6: 3117.1
A7: Detroit Lions | B7: 17 | C7: 6344 | D7: 373.2 | E7: 4303 | F7: 253.1 | G7: 2041 | H7: 120.1 | I7: 481 | J7: 28.3 | K7: offense/defense | L7: 17 | M7: 5642 | N7: 331.9 | O7: 3695 | P7: 217.4 | Q7: 1947 | R7: 114.5 | S7: 413 | T7: 24.3 | U7: 13960.7 | V7: 12402.1 | W7: 1558.6
A8: Chicago Bears | B8: 17 | C8: 6277 | D8: 369.2 | E8: 3826 | F8: 225.1 | G8: 2456 | H8: 144.5 | I8: 441 | J8: 25.9 | K8: offense/defense | L8: 17 | M8: 6150 | N8: 361.8 | O8: 3863 | P8: 227.2 | Q8: 2287 | R8: 134.5 | S8: 415 | T8: 24.4 | U8: 13781.7 | V8: 13479.9 | W8: 301.8
A9: San Francisco 49ers | B9: 17 | C9: 5974 | D9: 351.4 | E9: 4157 | F9: 244.5 | G9: 1817 | H9: 106.9 | I9: 437 | J9: 25.7 | K9: offense/defense | L9: 17 | M9: 5784 | N9: 340.2 | O9: 3951 | P9: 232.4 | Q9: 1833 | R9: 107.8 | S9: 371 | T9: 21.8 | U9: 13130.5 | V9: 12658.2 | W9: 472.3
A10: Seattle Seahawks | B10: 17 | C10: 5973 | D10: 351.4 | E10: 3877 | F10: 228.1 | G10: 2096 | H10: 123.3 | I10: 483 | J10: 28.4 | K10: offense/defense | L10: 17 | M10: 4855 | N10: 285.6 | O10: 3297 | P10: 193.9 | Q10: 1563 | R10: 91.9 | S10: 292 | T10: 17.2 | U10: 13177.2 | V10: 10612.6 | W10: 2564.6
A11: Indianapolis Colts | B11: 17 | C11: 5875 | D11: 345.6 | E11: 3873 | F11: 227.8 | G11: 2007 | H11: 118.1 | I11: 466 | J11: 27.4 | K11: offense/defense | L11: 17 | M11: 5947 | N11: 349.8 | O11: 4215 | P11: 247.9 | Q11: 1732 | R11: 101.9 | S11: 412 | T11: 24.2 | U11: 12956.9 | V11: 13046.8 | W11: -89.9
A12: Denver Broncos | B12: 17 | C12: 5825 | D12: 342.6 | E12: 3807 | F12: 223.9 | G12: 2018 | H12: 118.7 | I12: 401 | J12: 23.6 | K12: offense/defense | L12: 17 | M12: 4730 | N12: 278.2 | O12: 3182 | P12: 187.2 | Q12: 1548 | R12: 91.1 | S12: 311 | T12: 18.3 | U12: 12776.8 | V12: 10362.8 | W12: 2414
A13: Jacksonville Jaguars | B13: 17 | C13: 5735 | D13: 337.4 | E13: 3779 | F13: 222.3 | G13: 1956 | H13: 115.1 | I13: 474 | J13: 27.9 | K13: offense/defense | L13: 17 | M13: 5162 | N13: 303.6 | O13: 3707 | P13: 218.1 | Q13: 1455 | R13: 85.6 | S13: 336 | T13: 19.8 | U13: 12663.7 | V13: 11304.1 | W13: 1359.6
A14: Los Angeles Chargers | B14: 17 | C14: 5675 | D14: 333.8 | E14: 3608 | F14: 212.2 | G14: 2067 | H14: 121.6 | I14: 368 | J14: 21.6 | K14: offense/defense | L14: 17 | M14: 4849 | N14: 285.2 | O14: 3058 | P14: 179.9 | Q14: 1791 | R14: 105.4 | S14: 340 | T14: 20 | U14: 12424.2 | V14: 10645.5 | W14: 1778.7
... A34: Las Vegas Raiders | B34: 17 | C34: 4168 | D34: 245.2 | E34: 2851 | F34: 167.7 | G34: 1317 | H34: 77.5 | I34: 241 | J34: 14.2 | K34: offense/defense | L34: 17 | M34: 5403 | N34: 317.8 | O34: 3417 | P34: 201 | Q34: 1986 | R34: 116.8 | S34: 432 | T34: 25.4 | U34: 9098.6 | V34: 11916 | W34: -2817.4
C37: example | E37: Titans Of pass | F37: 166.1 | G37: Titans Of rush | H37: 93.5
E38: Raiders def pass | F38: 201 | G38: Raiders def rush | H38: 116.8 | M38: off pass | N38: off rush | O38: pf | P38: PA | Q38: def pass | R38: def rush | S38: raiders vs titans rank | T38: pass differential | U38: rush diff
E39: Raiders pass differential | F39: -34.9 | G39: Raiders rush differential | H39: -23.3 | K39: raiders | L39: -58.2 | M39: 167.7 | N39: 77.5 | O39: 14.2 | P39: 25.4 | Q39: 201 | R39: 116.8 | S39: -83.8 | T39: -34.9 | U39: -23.3 | V39: -142 | W39: -9.9
G40: Raiders offset game vs titans | H40: -58.2 | K40: titans | L40: -99.9 | M40: 166.1 | N40: 93.5 | O40: 16.7 | P40: 28.1 | Q40: 230.5 | R40: 114.6 | S40: -96.9 | T40: -62.8 | U40: -37.1 | V40: -196.8 | W40: -13.8
W41: -3.8
E42: Raiders of pass | F42: 167.7 | G42: Raiders of rush | H42: 77.5 | W42: prediction
E43: Titans def pass | F43: 230.5 | G43: titans def rush | H43: 114.6 | V43: spread | W43: Raiders -3.8
E44: titans pass differential | F44: -62.8 | G44: titans rush differential | H44: -37.1 | V44: spread | W44: Titans +3.8
G45: titans offset game vs raiders | H45: -99.9 | V45: final score | W45: 14 - 10
V46: Raiders win
D47: Takeaways | G47: Giveaways
A48: Team | B48: GP | C48: DIFF | D48: INT | E48: FUM | F48: TOTAL | G48: INT | H48: FUM | I48: TOTAL
A49: Chicago Bears | B49: 17 | C49: 22 | D49: 23 | E49: 10 | F49: 33 | G49: 7 | H49: 4 | I49: 11
A50: Houston Texans | B50: 17 | C50: 17 | D50: 19 | E50: 10 | F50: 29 | G50: 9 | H50: 3 | I50: 12
A51: Jacksonville Jaguars | B51: 17 | C51: 13 | D51: 22 | E51: 9 | F51: 31 | G51: 12 | H51: 6 | I51: 18
A52: Pittsburgh Steelers | B52: 17 | C52: 12 | D52: 15 | E52: 12 | F52: 27 | G52: 9 | H52: 6 | I52: 15
A53: Los Angeles Rams | B53: 17 | C53: 11 | D53: 16 | E53: 10 | F53: 26 | G53: 8 | H53: 7 | I53: 15
A54: Tampa Bay Buccaneers | B54: 17 | C54: 7 | D54: 13 | E54: 10 | F54: 23 | G54: 11 | H54: 5 | I54: 16
A55: Philadelphia Eagles | B55: 17 | C55: 6 | D55: 12 | E55: 9 | F55: 21 | G55: 7 | H55: 8 | I55: 15
A56: Atlanta Falcons | B56: 17 | C56: 5 | D56: 16 | E56: 7 | F56: 23 | G56: 8 | H56: 10 | I56: 18
A57: Detroit Lions | B57: 17 | C57: 4 | D57: 13 | E57: 6 | F57: 19 | G57: 8 | H57: 7 | I57: 15
A58: New England Patriots | B58: 17 | C58: 3 | D58: 10 | E58: 9 | F58: 19 | G58: 8 | H58: 8 | I58: 16
A59: Los Angeles Chargers | B59: 17 | C59: 2 | D59: 19 | E59: 4 | F59: 23 | G59: 14 | H59: 7 | I59: 21
A60: Buffalo Bills | B60: 17 | C60: 1 | D60: 13 | E60: 7 | F60: 20 | G60: 10 | H60: 9 | I60: 19
... A80: New York Jets | B80: 17 | C80: -19 | D80: 0 | E80: 4 | F80: 4 | G80: 13 | H80: 10 | I80: 23
...

Sheet Sheet2
A1: Team | B1: Off Pass Yds | C1: Off Rush Yds | D1: Off PF | E1: Def Pass Yds | F1: Def Rush Yds | G1: Def PA | H1: TO Diff | I1: Takeaways | J1: Giveaways | K1: KR Avg | L1: PR Avg | M1: Net Pts | N1: Net Yds
A2: Arizona Cardinals | B2: 4354 | C2: 1583 | D2: 355 | E2: 4128 | F2: 2158 | G2: 488 | H2: 4 | I2: 19 | J2: 15 | K2: 25.1 | L2: 11.4 | M2: -133 | N2: -349
A3: Atlanta Falcons | B3: 3703 | C3: 2138 | D3: 353 | E3: 3773 | F3: 2146 | G3: 401 | H3: 9 | I3: 23 | J3: 14 | K3: 22.9 | L3: 7 | M3: -48 | N3: -78
A4: Baltimore Ravens | B4: 3278 | C4: 2662 | D4: 424 | E4: 4403 | F4: 1813 | G4: 398 | H4: 2 | I4: 20 | J4: 18 | K4: 25.8 | L4: 12.4 | M4: 26 | N4: -276
A5: Buffalo Bills | B5: 3981 | C5: 2714 | D5: 481 | E5: 2894 | F5: 2315 | G5: 365 | H5: 5 | I5: 20 | J5: 15 | K5: 24.5 | L5: 9 | M5: 116 | N5: 1486
A6: Carolina Panthers | B6: 3304 | C6: 1977 | D6: 311 | E6: 3657 | F6: 2096 | G6: 380 | H6: 3 | I6: 21 | J6: 18 | K6: 24 | L6: 9 | M6: -69 | N6: -472
A7: Chicago Bears | B7: 3991 | C7: 2451 | D7: 441 | E7: 4067 | F7: 2287 | G7: 415 | H7: 21 | I7: 33 | J7: 12 | K7: 26.4 | L7: 11 | M7: 26 | N7: 88
A8: Cincinnati Bengals | B8: 4244 | C8: 1591 | D8: 414 | E8: 4175 | F8: 2100 | G8: 492 | H8: -2 | I8: 20 | J8: 22 | K8: 25 | L8: 9 | M8: -78 | N8: -440
A9: Cleveland Browns | B9: 3152 | C9: 1649 | D9: 279 | E9: 3220 | F9: 1979 | G9: 379 | H9: -6 | I9: 18 | J9: 24 | K9: 24 | L9: 9 | M9: -100 | N9: -398
A10: Dallas Cowboys | B10: 4735 | C10: 2136 | D10: 471 | E10: 4521 | F10: 2200 | G10: 511 | H10: -6 | I10: 12 | J10: 18 | K10: 25.6 | L10: 6.8 | M10: -40 | N10: 150
A11: Denver Broncos | B11: 3931 | C11: 2018 | D11: 401 | E11: 3606 | F11: 1548 | G11: 311 | H11: -2 | I11: 14 | J11: 16 | K11: 25.3 | L11: 14.2 | M11: 90 | N11: 795
A12: Detroit Lions | B12: 4567 | C12: 2041 | D12: 481 | E12: 4027 | F12: 1947 | G12: 413 | H12: 6 | I12: 19 | J12: 13 | K12: 26.6 | L12: 8.3 | M12: 68 | N12: 634
A13: Green Bay Packers | B13: 3845 | C13: 2037 | D13: 391 | E13: 3516 | F13: 2001 | G13: 360 | H13: 2 | I13: 14 | J13: 12 | K13: 25.2 | L13: 5.6 | M13: 31 | N13: 365
... A33: Washington Commanders | B33: 3329 | C33: 2290 | D33: 356 | E33: 4371 | F33: 2100 | G33: 451 | H33: -6 | I33: 10 | J33: 16 | K33: 24 | L33: 9 | M33: -95 | N33: -852

Sheet prediction logic
A1: Team/offense | B1: madden player | C1: total avg yards/game | D1: avg points/ game | E1: Team Turnovers | F1: Avg Rush | G1: Avg pass
A2: Bears | B2: =89+89+79 -> 257 | C2: =Sheet1!D8 -> 369.2 | D2: =Sheet1!J8 -> 25.9 | E2: ='turnover and special teams'!I3 -> 11 | F2: =Sheet1!H8 -> 144.5 | G2: =Sheet1!F8 -> 225.1
A3: vs
A4: Browns | B4: =95+93+91 -> 279 | C4: =Sheet1!D32 -> 262.1 | D4: =Sheet1!J32 -> 16.4 | E4: ='turnover and special teams'!I29 -> 25 | F4: =Sheet1!H32 -> 97 | G4: =Sheet1!F32 -> 165.2
A6: Team/defense
A7: Bears | B7: =87+90+93 -> 270 | C7: =Sheet1!N8 -> 361.8 | D7: =Sheet1!T8 -> 24.4 | E7: ='turnover and special teams'!F3 -> 33 | F7: =Sheet1!R8 -> 134.5 | G7: =Sheet1!P8 -> 227.2
A8: vs
A9: Browns | B9: =92+84+99 -> 275 | C9: =Sheet1!N32 -> 283.6 | D9: =Sheet1!T32 -> 22.3 | E9: ='turnover and special teams'!F29 -> 18 | F9: =Sheet1!R32 -> 116.4 | G9: =Sheet1!P32 -> 167.2
A11: Team Differential
A12: Bears | B12: =B2-B7 -> -13 | C12: =C2-C7 -> 7.4 | D12: =D2-D7 -> 1.5 | E12: =E2-E9 -> -7 | F12: =F2-F9 -> 28.1 | G12: =G2-G9 -> 57.9
A13: vs
A14: Browns | B14: =B4-B9 -> 4 | C14: =C4-C9 -> -21.5 | D14: =D4-D9 -> -5.9 | E14: =E4-E7 -> -8 | F14: =F4-F7 -> -37.5 | G14: =G4-G7 -> -62
F16: Bears | G16: =(E12+F12+G12+C12+D12)/10+B12 -> -4.21
F17: Browns | G17: =(E14+F14+G14+C14+D14)/10+B14 -> -9.49
G18: =G17-G16 -> -5.28 | H18: Bears Win
F20: Spread | G20: Bears | H20: -5.28 | I20: Browns

Sheet Sheet3
A1: Team | B1: Net Pts | C1: Net Yds | D1: TO Diff
A2: Arizona Cardinals | B2: -133 | C2: -349 | D2: 4
A3: Atlanta Falcons | B3: -48 | C3: -78 | D3: 9
A4: Baltimore Ravens | B4: 26 | C4: -276 | D4: 2
A5: Buffalo Bills | B5: 116 | C5: 1486 | D5: 5
A6: Carolina Panthers | B6: -69 | C6: -472 | D6: 3
A7: Chicago Bears | B7: 26 | C7: 88 | D7: 21
A8: Cincinnati Bengals | B8: -78 | C8: -440 | D8: -2
A9: Cleveland Browns | B9: -100 | C9: -398 | D9: -6
A10: Dallas Cowboys | B10: -40 | C10: 150 | D10: -6
A11: Denver Broncos | B11: 90 | C11: 795 | D11: -2
A12: Detroit Lions | B12: 68 | C12: 634 | D12: 6
A13: Green Bay Packers | B13: 31 | C13: 365 | D13: 2
... A34: Grand Total | B34: 0 | C34: 1010 | D34: 78

Sheet madden player ratings
A2: Team | B2: Team Average | C2: Player | D2: Rating | E2: Position
A3: Chiefs | B3: 84 | C3: Patrick Mahomes | D3: 99 | E3: QB
A4: Chiefs | B4: 84 | C4: Travis Kelce | D4: 97 | E4: TE
A5: Chiefs | B5: 84 | C5: Chris Jones | D5: 96 | E5: DT
A6: Chiefs | B6: 84 | C6: Creed Humphrey | D6: 95 | E6: C
A7: Chiefs | B7: 84 | C7: Trent McDuffie | D7: 93 | E7: CB
A8: 49ers | B8: 86 | C8: Christian McCaffrey | D8: 99 | E8: RB
A9: 49ers | B9: 86 | C9: Trent Williams | D9: 98 | E9: LT
A10: 49ers | B10: 86 | C10: Fred Warner | D10: 97 | E10: MLB
A11: 49ers | B11: 86 | C11: George Kittle | D11: 96 | E11: TE
A12: 49ers | B12: 86 | C12: Nick Bosa | D12: 96 | E12: DE
A13: Ravens | B13: 85 | C13: Lamar Jackson | D13: 98 | E13: QB
A14: Ravens | B14: 85 | C14: Roquan Smith | D14: 96 | E14: MLB
... A82: Vikings | B82: 80 | C82: Aaron Jones | D82: 88 | E82: RB
A83: Falcons | B83: 81 | C83: Jessie Bates III | D83: 97
A84: Falcons | B84: 81 | C84: Chris Lindstrom | D84: 94
A85: Falcons | B85: 81 | C85: Justin Simmons | D85: 92
A86: Falcons | B86: 81 | C86: Kirk Cousins | D86: 89
A87: Falcons | B87: 81 | C87: Bijan Robinson | D87: 88
A88: Saints | B88: 80 | C88: Demario Davis | D88: 93
A89: Saints | B89: 80 | C89: Tyrann Mathieu | D89: 91
A90: Saints | B90: 80 | C90: Alvin Kamara | D90: 89
A91: Saints | B91: 80 | C91: Marshon Lattimore | D91: 89
A92: Saints | B92: 80 | C92: Cameron Jordan | D92: 88
A93: Buccaneers | B93: 81 | C93: Antoine Winfield Jr. | D93: 95
A94: Buccaneers | B94: 81 | C94: Mike Evans | D94: 92
... A162: Cardinals | B162: 77 | C162: Jalen Thompson | D162: 85

Sheet turnover and special teams
B1: games played | C1: turn over ratio | D1: Takeaways | G1: Giveaways
A2: Team | B2: GP | C2: DIFF | D2: INT | E2: FUM | F2: TOTAL | G2: INT | H2: FUM | I2: TOTAL
A3: Chicago Bears | B3: 17 | C3: 22 | D3: 23 | E3: 10 | F3: 33 | G3: 7 | H3: 4 | I3: 11
A4: Houston Texans | B4: 17 | C4: 17 | D4: 19 | E4: 10 | F4: 29 | G4: 9 | H4: 3 | I4: 12
A5: Jacksonville Jaguars | B5: 17 | C5: 13 | D5: 22 | E5: 9 | F5: 31 | G5: 12 | H5: 6 | I5: 18
A6: Pittsburgh Steelers | B6: 17 | C6: 12 | D6: 15 | E6: 12 | F6: 27 | G6: 9 | H6: 6 | I6: 15
A7: Los Angeles Rams | B7: 17 | C7: 11 | D7: 16 | E7: 10 | F7: 26 | G7: 8 | H7: 7 | I7: 15
A8: Tampa Bay Buccaneers | B8: 17 | C8: 7 | D8: 13 | E8: 10 | F8: 23 | G8: 11 | H8: 5 | I8: 16
A9: Philadelphia Eagles | B9: 17 | C9: 6 | D9: 12 | E9: 9 | F9: 21 | G9: 7 | H9: 8 | I9: 15
A10: Atlanta Falcons | B10: 17 | C10: 5 | D10: 16 | E10: 7 | F10: 23 | G10: 8 | H10: 10 | I10: 18
A11: Detroit Lions | B11: 17 | C11: 4 | D11: 13 | E11: 6 | F11: 19 | G11: 8 | H11: 7 | I11: 15
A12: New England Patriots | B12: 17 | C12: 3 | D12: 10 | E12: 9 | F12: 19 | G12: 8 | H12: 8 | I12: 16
A13: Los Angeles Chargers | B13: 17 | C13: 2 | D13: 19 | E13: 4 | F13: 23 | G13: 14 | H13: 7 | I13: 21
A14: Buffalo Bills | B14: 17 | C14: 1 | D14: 13 | E14: 7 | F14: 20 | G14: 10 | H14: 9 | I14: 19
... A34: New York Jets | B34: 17 | C34: -19 | D34: 0 | E34: 4 | F34: 4 | G34: 13 | H34: 10 | I34: 23
A37: Touchdowns | K37: Kicking | M37: Misc
A38: Team | B38: Tot | C38: R | D38: P | E38: KR | F38: PR | G38: IR | H38: FR | I38: BK | J38: BP | K38: FGR | L38: PAT | M38: FG | N38: Conv | O38: Saf | P38: Pts
A39: Seattle Seahawks | B39: 31 | C39: 9 | D39: 20 | E39: 0 | F39: 1 | G39: 0 | H39: 1 | I39: 0 | J39: 0 | K39: 0 | L39: 25/26 | M39: 25/31 | N39: 3 | O39: 0 | P39: 292
A40: Houston Texans | B40: 35 | C40: 13 | D40: 20 | E40: 1 | F40: 1 | G40: 0 | H40: 0 | I40: 0 | J40: 0 | K40: 0 | L40: 27/30 | M40: 18/27 | N40: 2 | O40: 0 | P40: 295
A41: Denver Broncos | B41: 29 | C41: 11 | D41: 18 | E41: 0 | F41: 0 | G41: 0 | H41: 0 | I41: 0 | J41: 0 | K41: 0 | L41: 24/27 | M41: 37/39 | N41: 0 | O41: 1 | P41: 311
A42: New England Patriots | B42: 38 | C42: 11 | D42: 25 | E42: 0 | F42: 1 | G42: 1 | H42: 0 | I42: 0 | J42: 0 | K42: 0 | L42: 33/35 | M42: 19/23 | N42: 1 | O42: 0 | P42: 320
A43: Philadelphia Eagles | B43: 34 | C43: 20 | D43: 14 | E43: 0 | F43: 0 | G43: 0 | H43: 0 | I43: 0 | J43: 0 | K43: 0 | L43: 28/31 | M43: 29/35 | N43: 2 | O43: 1 | P43: 325
A44: Kansas City Chiefs | B44: 33 | C44: 14 | D44: 18 | E44: 0 | F44: 0 | G44: 1 | H44: 0 | I44: 0 | J44: 0 | K44: 0 | L44: 31/32 | M44: 31/32 | N44: 1 | O44: 2 | P44: 328
A45: Minnesota Vikings | B45: 32 | C45: 13 | D45: 15 | E45: 0 | F45: 0 | G45: 3 | H45: 1 | I45: 0 | J45: 0 | K45: 0 | L45: 31/31 | M45: 36/45 | N45: 1 | O45: 0 | P45: 333
A46: Jacksonville Jaguars | B46: 40 | C46: 13 | D46: 25 | E46: 0 | F46: 0 | G46: 0 | H46: 2 | I46: 0 | J46: 0 | K46: 0 | L46: 32/33 | M46: 20/24 | N46: 2 | O46: 0 | P46: 336
A47: Los Angeles Chargers | B47: 35 | C47: 16 | D47: 16 | E47: 0 | F47: 1 | G47: 2 | H47: 0 | I47: 0 | J47: 0 | K47: 0 | L47: 30/32 | M47: 32/36 | N47: 2 | O47: 0 | P47: 340
A48: Los Angeles Rams | B48: 38 | C48: 8 | D48: 26 | E48: 0 | F48: 1 | G48: 2 | H48: 0 | I48: 1 | J48: 0 | K48: 0 | L48: 31/32 | M48: 27/32 | N48: 3 | O48: 0 | P48: 346
A49: Green Bay Packers | B49: 39 | C49: 15 | D49: 24 | E49: 0 | F49: 0 | G49: 0 | H49: 0 | I49: 0 | J49: 0 | K49: 0 | L49: 31/33 | M49: 29/33 | N49: 3 | O49: 0 | P49: 360
A50: Buffalo Bills | B50: 43 | C50: 24 | D50: 19 | E50: 0 | F50: 0 | G50: 0 | H50: 0 | I50: 0 | J50: 0 | K50: 0 | L50: 34/37 | M50: 23/25 | N50: 2 | O50: 0 | P50: 365
... A70: Dallas Cowboys | B70: 59 | C70: 24 | D70: 35 | E70: 0 | F70: 0 | G70: 0 | H70: 0 | I70: 0 | J70: 0 | K70: 0 | L70: 53/54 | M70: 32/34 | N70: 3 | O70: 1 | P70: 511
A72: KEY: Tot = Total Touchdowns, R = Rushing Touchdowns, P = Touchdown Receptions, KR = Kickoff Return Touchdowns, PR = Punt Return Touchdowns, IR = Interception Return Touchdowns, FR = Fumble Return Touchdowns, BK = Blocked Field Goal Touchdowns, FGR = Missed Field Goal Return Touchdowns, PAT = Extra Points Made, FG = Field Goals Made, Conv = Rushing & Receiving Conversions, Saf = Safeties, Pts = Points Scored
